<?xml version="1.0" encoding="utf-8"?>
<robot name="heron">
    <link name="base_footprint">
    </link>
    <joint name="base_footprint" type="fixed">
        <parent link="base_footprint"/>
        <child link="base_link"/>
        <origin xyz="0 0 0.1" rpy="0 0 0"/>
    </joint>

    <link name="base_link">
        <inertial>
            <origin xyz="-0.15 0.025 0.0" rpy="0 0 1.57079"/>
            <mass value="25"/>
            <inertia
            ixx="4.73345232681242"
            ixy="-6.13913566072873E-06"
            ixz="-1.89872416704455E-05"
            iyy="6.95202353462315"
            iyz="-8.07624704791103E-06"
            izz="3.18752499734018" />
            </inertial>
        <visual>
            <origin xyz="-0.15 0.025 0.0" rpy="0 0 1.57079"/>
            <geometry>
                <mesh filename="package://seminaire/meshes/base_link.STL"/>
                <material>
                    <color rgba="1 0.3 0.5 0.5"/>
                </material>
            </geometry>
        </visual>
    </link>


    <link name="wheel_fl">
        <inertial>
            <origin xyz="0 0 0" rpy="0 0 0"/>
            <mass value="0.389968906998643" />
            <inertia
            ixx="0.000322138046158454"
            ixy="-6.65852858947508E-37"
            ixz="-1.86618052242594E-37"
            iyy="0.00048299257130799"
            iyz="5.80382085092595E-22"
            izz="0.000322138046158454" />
        </inertial>
        <visual>
            <origin xyz="0 0 0" rpy="0 0 0"/>
            <geometry>
                <mesh filename="package://seminaire/meshes/wheel_FL.dae" scale="0.4 0.5 0.4"/>
            </geometry>
        </visual>
    </link>
    <joint name="wheel_fl" type="continuous">
        <parent link="base_link"/>
        <child link="wheel_fl"/>
        <origin xyz="0.2 0.216235 -0.06" rpy="0 0 0"/>
        <axis xyz="0 1 0" />
        <limit effort="9.1201845" velocity="8.79645942"/>
    </joint>

    <link name="wheel_fr">
        <inertial>
            <origin xyz="0 0 0" rpy="0 0 0"/>
            <mass value="0.389968906998643" />
            <inertia
            ixx="0.000322138046158454"
            ixy="-6.65852858947508E-37"
            ixz="-1.86618052242594E-37"
            iyy="0.00048299257130799"
            iyz="5.80382085092595E-22"
            izz="0.000322138046158454" />
        </inertial>
        <visual>
            <origin xyz="0 0 0" rpy="0 0 0"/>
            <geometry>
                <mesh filename="package://seminaire/meshes/wheel_FR.dae" scale="0.4 0.5 0.4"/>
            </geometry>
        </visual>
    </link>
    <joint name="wheel_fr" type="continuous">
        <parent link="base_link"/>
        <child link="wheel_fr"/>
        <origin xyz="0.2 -0.216235 -0.06" rpy="0 0 0"/>
        <axis xyz="0 1 0" />
        <limit effort="9.1201845" velocity="8.79645942"/>
    </joint>

    <link name="wheel_bl">
        <inertial>
            <origin xyz="0 0 0" rpy="0 0 0"/>
            <mass value="0.389968906998643" />
            <inertia
            ixx="0.000322138046158454"
            ixy="-6.65852858947508E-37"
            ixz="-1.86618052242594E-37"
            iyy="0.00048299257130799"
            iyz="5.80382085092595E-22"
            izz="0.000322138046158454" />
        </inertial>
        <visual>
            <origin xyz="0 0 0" rpy="0 0 0"/>
            <geometry>
                <mesh filename="package://seminaire/meshes/wheel_BL.dae" scale="0.4 0.5 0.4"/>
            </geometry>
        </visual>
    </link>
    <joint name="wheel_bl" type="continuous">
        <parent link="base_link"/>
        <child link="wheel_bl"/>
        <origin xyz="-0.2 0.216235 -0.06" rpy="0 0 0"/>
        <axis xyz="0 1 0" />
        <limit effort="9.1201845" velocity="8.79645942"/>
    </joint>

    <link name="wheel_br">
        <inertial>
            <origin xyz="0 0 0" rpy="0 0 0"/>
            <mass value="0.389968906998643" />
            <inertia
            ixx="0.000322138046158454"
            ixy="-6.65852858947508E-37"
            ixz="-1.86618052242594E-37"
            iyy="0.00048299257130799"
            iyz="5.80382085092595E-22"
            izz="0.000322138046158454" />
        </inertial>
        <visual>
            <origin xyz="0 0 0" rpy="0 0 0"/>
            <geometry>
                <mesh filename="package://seminaire/meshes/wheel_BR.dae" scale="0.4 0.5 0.4"/>
            </geometry>
        </visual>
    </link>
    <joint name="wheel_br" type="continuous">
        <parent link="base_link"/>
        <child link="wheel_br"/>
        <origin xyz="-0.2 -0.216235 -0.06" rpy="0 0 0"/>
        <axis xyz="0 1 0" />
        <limit effort="9.1201845" velocity="8.79645942"/>
    </joint>


    <link name="support">
        <inertial>
            <origin xyz="-0.015 -0.19 -0.1" rpy="1.5707963267949 0 1.5707963267949"/>
            <mass value="0.389968906998643" />
            <inertia
            ixx="0.20"
            ixy="0"
            ixz="0"
            iyy="0.10"
            iyz="-0.08"
            izz="0.14" />
        </inertial>
        <visual>
            <origin xyz="-0.015 -0.19 -0.1" rpy="1.5707963267949 0 1.5707963267949"/>
            <geometry>
                <mesh filename="package://seminaire/meshes/support.STL"/>
            </geometry>
        </visual>
    </link>
    <joint name="support" type="fixed">
        <parent link="base_link"/>
        <child link="support"/>
        <origin xyz="-0.3 0 0" rpy="0 0 0"/>
    </joint>


    <link name="plate">
        <inertial>
            <origin xyz="-0.33 -0.25 -0.1" rpy="1.5707963267949 0 1.5707963267949"/>
            <mass value="0.389968906998643" />
            <inertia
            ixx="1.47"
            ixy="-0.09"
            ixz="-0.31"
            iyy="1.46"
            iyz="0.39"
            izz="0.35" /> 
        </inertial>
        <visual>
            <origin xyz="-0.33 -0.25 -0.1" rpy="1.5707963267949 0 1.5707963267949"/>
            <geometry>
                <mesh filename="package://seminaire/meshes/plate.STL"/>
            </geometry>
        </visual>
    </link>
    <joint name="plate" type="prismatic">
        <parent link="base_link"/>
        <child link="plate"/>
        <origin xyz="-0.32 0 0.13" rpy="0 0 0"/>
        <axis xyz="0 0 1" />
        <limit effort="147" lower="0.0" upper="0.386" velocity="0.039"/>
    </joint>

</robot>